<?xml version="1.0" encoding="utf-8"?>
<!-- This URDF was automatically created by SolidWorks to URDF Exporter! Originally created by Stephen Brawner (brawner@gmail.com) 
     Commit Version: 1.6.0-1-g15f4949  Build Version: 1.6.7594.29634
     For more information, please see http://wiki.ros.org/sw_urdf_exporter -->
<robot
  name="puma560_description">
  <link
    name="base_link">
    <inertial>
      <origin
        xyz="-9.5392E-11 0.021962 0.19252"
        rpy="0 0 0" />
      <mass
        value="15.787" />
      <inertia
        ixx="0.55024"
        ixy="-2.8629E-11"
        ixz="-1.6745E-10"
        iyy="0.50424"
        iyz="0.022162"
        izz="0.16071" />
    </inertial>
    <visual>
      <origin
        xyz="0 0 0"
        rpy="0 0 0" />
      <geometry>
        <mesh
          filename="package://puma560_description/meshes/base_link.STL" />
      </geometry>
      <material
        name="white">
        <color
          rgba="1 1 1 1" />
      </material>
    </visual>
    <collision>
      <origin
        xyz="0 0 0"
        rpy="0 0 0" />
      <geometry>
        <mesh
          filename="package://puma560_description/meshes/base_link.STL" />
      </geometry>
    </collision>
  </link>
  <link
    name="waist_link">
    <inertial>
      <origin
        xyz="2.714E-07 -0.022505 -0.0027897"
        rpy="0 0 0" />
      <mass
        value="4.4341" />
      <inertia
        ixx="0.027328"
        ixy="-1.206E-08"
        ixz="-3.911E-09"
        iyy="0.013316"
        iyz="0.00027854"
        izz="0.027164" />
    </inertial>
    <visual>
      <origin
        xyz="0 0 0"
        rpy="0 0 0" />
      <geometry>
        <mesh
          filename="package://puma560_description/meshes/waist_link.STL" />
      </geometry>
      <material
        name="white">
        <color
          rgba="1 1 1 1" />
      </material>
    </visual>
    <collision>
      <origin
        xyz="0 0 0"
        rpy="0 0 0" />
      <geometry>
        <mesh
          filename="package://puma560_description/meshes/waist_link.STL" />
      </geometry>
    </collision>
  </link>
  <joint
    name="base_waist_joint"
    type="revolute">
    <origin
      xyz="0 0 0.62357"
      rpy="0 0 -0.018511" />
    <parent
      link="base_link" />
    <child
      link="waist_link" />
    <axis
      xyz="0 0 1" />
    <limit
      lower="-2.3562"
      upper="2.3562"
      effort="50"
      velocity="82" />
  </joint>
  <link
    name="shoulder_link">
    <inertial>
      <origin
        xyz="0.082737 0.0031596 -4.6776E-05"
        rpy="0 0 0" />
      <mass
        value="16.847" />
      <inertia
        ixx="0.09723"
        ixy="0.0043475"
        ixz="-7.8857E-06"
        iyy="0.65976"
        iyz="4.8383E-05"
        izz="0.59657" />
    </inertial>
    <visual>
      <origin
        xyz="0 0 0"
        rpy="0 0 0" />
      <geometry>
        <mesh
          filename="package://puma560_description/meshes/shoulder_link.STL" />
      </geometry>
      <material
        name="gris01">
        <color
          rgba="0.79216 0.81961 0.93333 1" />
      </material>
    </visual>
    <collision>
      <origin
        xyz="0 0 0"
        rpy="0 0 0" />
      <geometry>
        <mesh
          filename="package://puma560_description/meshes/shoulder_link.STL" />
      </geometry>
    </collision>
  </link>
  <joint
    name="waist_shoulder_joint"
    type="revolute">
    <origin
      xyz="0 -0.21844 0"
      rpy="0 -0.083022 0" />
    <parent
      link="waist_link" />
    <child
      link="shoulder_link" />
    <axis
      xyz="0 1 0" />
    <limit
      lower="-2.3562"
      upper="2.3562"
      effort="50"
      velocity="74" />
  </joint>
  <link
    name="elbow_link">
    <inertial>
      <origin
        xyz="0.088774 1.5623E-06 -1.1788E-06"
        rpy="0 0 0" />
      <mass
        value="4.6025" />
      <inertia
        ixx="0.0091916"
        ixy="2.2739E-06"
        ixz="4.837E-07"
        iyy="0.087355"
        iyz="3.6529E-07"
        izz="0.082615" />
    </inertial>
    <visual>
      <origin
        xyz="0 0 0"
        rpy="0 0 0" />
      <geometry>
        <mesh
          filename="package://puma560_description/meshes/elbow_link.STL" />
      </geometry>
      <material
        name="white">
        <color
          rgba="1 1 1 1" />
      </material>
    </visual>
    <collision>
      <origin
        xyz="0 0 0"
        rpy="0 0 0" />
      <geometry>
        <mesh
          filename="package://puma560_description/meshes/elbow_link.STL" />
      </geometry>
    </collision>
  </link>
  <joint
    name="shoulder_elbow_link"
    type="revolute">
    <origin
      xyz="0.4318 0.0889 0"
      rpy="3.1416 0.057886 0" />
    <parent
      link="shoulder_link" />
    <child
      link="elbow_link" />
    <axis
      xyz="0 -1 0" />
    <limit
      lower="-2.3562"
      upper="2.3562"
      effort="20"
      velocity="122" />
  </joint>
  <link
    name="wrist_roll_link">
    <inertial>
      <origin
        xyz="-0.032409 -1.3878E-17 0"
        rpy="0 0 0" />
      <mass
        value="0.47079" />
      <inertia
        ixx="0.00046683"
        ixy="-6.0139E-20"
        ixz="1.0912E-19"
        iyy="0.00073772"
        iyz="-3.134E-20"
        izz="0.00077289" />
    </inertial>
    <visual>
      <origin
        xyz="0 0 0"
        rpy="0 0 0" />
      <geometry>
        <mesh
          filename="package://puma560_description/meshes/wrist_roll_link.STL" />
      </geometry>
      <material
        name="gris2">
        <color
          rgba="0.79216 0.81961 0.93333 1" />
      </material>
    </visual>
    <collision>
      <origin
        xyz="0 0 0"
        rpy="0 0 0" />
      <geometry>
        <mesh
          filename="package://puma560_description/meshes/wrist_roll_link.STL" />
      </geometry>
    </collision>
  </link>
  <joint
    name="elbow_wrist_roll_joint"
    type="revolute">
    <origin
      xyz="0.43209 0 0"
      rpy="-3.1305 0 0" />
    <parent
      link="elbow_link" />
    <child
      link="wrist_roll_link" />
    <axis
      xyz="1 0 0" />
    <limit
      lower="-2.3562"
      upper="2.3562"
      effort="20"
      velocity="228" />
  </joint>
  <link
    name="wrist_bend_link">
    <inertial>
      <origin
        xyz="0.010974 -6.7753E-10 1.7546E-09"
        rpy="0 0 0" />
      <mass
        value="0.077406" />
      <inertia
        ixx="1.6966E-05"
        ixy="6.3394E-13"
        ixz="-3.0414E-12"
        iyy="4.5414E-05"
        iyz="1.1518E-11"
        izz="4.3032E-05" />
    </inertial>
    <visual>
      <origin
        xyz="0 0 0"
        rpy="0 0 0" />
      <geometry>
        <mesh
          filename="package://puma560_description/meshes/wrist_bend_link.STL" />
      </geometry>
      <material
        name="gris2">
        <color
          rgba="0.79216 0.81961 0.93333 1" />
      </material>
    </visual>
    <collision>
      <origin
        xyz="0 0 0"
        rpy="0 0 0" />
      <geometry>
        <mesh
          filename="package://puma560_description/meshes/wrist_bend_link.STL" />
      </geometry>
    </collision>
  </link>
  <joint
    name="wrist_roll_bend_joint"
    type="revolute">
    <origin
      xyz="0 0 0"
      rpy="0 -0.19722 0" />
    <parent
      link="wrist_roll_link" />
    <child
      link="wrist_bend_link" />
    <axis
      xyz="0 -1 0" />
    <limit
      lower="-2.3562"
      upper="2.3562"
      effort="15"
      velocity="120" />
  </joint>
</robot>